Workbook
Name AddLoans: '1-StartingPoint'!$D$36
Name Advertising: '1-StartingPoint'!$C$26
Name Annual_Interest_Rate: #REF!
Name Beg_Bal: #REF!
Name Buildings: '1-StartingPoint'!$C$10
Name Category1: '3a-SalesForecastYear1'!$B$9
Name Category1_Annual_Sales: '3a-SalesForecastYear1'!$O$19
Name Category1_SalesPrice: '3a-SalesForecastYear1'!#REF!
Name Category2: '3a-SalesForecastYear1'!$B$10
Name Category2_Annual_Sales: '3a-SalesForecastYear1'!$O$25
Name Category2_SalesPrice: '3a-SalesForecastYear1'!#REF!
Name Category3: '3a-SalesForecastYear1'!$B$11
Name Category3_Annual_Sales: '3a-SalesForecastYear1'!$O$31
Name Category3_SalesPrice: '3a-SalesForecastYear1'!#REF!
Name Category4: '3a-SalesForecastYear1'!$B$12
Name Category4_Annual_Sales: '3a-SalesForecastYear1'!$O$37
Name Category4_SalesPrice: '3a-SalesForecastYear1'!#REF!
Name Category5: '3a-SalesForecastYear1'!$B$13
Name Category5_Annual_Sales: '3a-SalesForecastYear1'!$O$43
Name Category5_SalesPrice: '3a-SalesForecastYear1'!#REF!
Name Category6: '3a-SalesForecastYear1'!$B$14
Name Category6_Annual_Sales: '3a-SalesForecastYear1'!$O$49
Name Category6_SalesPrice: '3a-SalesForecastYear1'!#REF!
Name Catergory6: '3a-SalesForecastYear1'!$B$14
Name CCDebt: '1-StartingPoint'!$D$39
Name COGS_Annual_Total: '3a-SalesForecastYear1'!$O$54
Name CommLoan: '1-StartingPoint'!$D$37
Name CommMortgage: '1-StartingPoint'!$D$38
Name ContingencyCash: '1-StartingPoint'!#REF!
Name Equipment: '1-StartingPoint'!$C$12
Name Extra_Pay: #REF!
Name Furniture: '1-StartingPoint'!$C$13
Name Growth_Rate_Yr2: '3b-SalesForecastYrs1-3'!$C$7
Name Growth_Rate_Yr3: '3b-SalesForecastYrs1-3'!$C$8
Name Info_Entered: #REF!
Name Int: #REF!
Name InterestRate_ShortTerm: #REF!
Name Inventory: '1-StartingPoint'!$C$21
Name Land: '1-StartingPoint'!$C$9
Name Last_Row: IF(Values_Entered,Header_Row+Number_of_Payments,Header_Row)
Name LeaseImprovements: '1-StartingPoint'!$C$11
Name LegalAcctFees: '1-StartingPoint'!$C$22
Name Licenses: '1-StartingPoint'!$C$27
Name Loan_Amount: #REF!
Name Loan_Term_Years: #REF!
Name LoanAmount_ShortTerm: #REF!
Name LoanTermYears_ShortTerm: #REF!
Name Margin_Annual_Total: '3a-SalesForecastYear1'!$O$55
Name Misc_Expenses: '5a-OpExYear1'!$O$19
Name Monthly_Payment_LongTerm: #REF!
Name NetIncomeY1: '7b-IncomeStatementYrs1-3'!$C$59
Name NetIncomeY2: '7b-IncomeStatementYrs1-3'!$E$59
Name NetIncomeY3: '7b-IncomeStatementYrs1-3'!$G$59
Name Number_of_Payments: MATCH(0.01,End_Bal,-1)+1
Name OfficeSupplies_Expenses: '5a-OpExYear1'!$O$20
Name Other_Expenses: '5a-OpExYear1'!$O$21
Name OtherBankDebt: '1-StartingPoint'!$D$41
Name OtherFixedAssets: '1-StartingPoint'!$C$15
Name OtherStartUp: '1-StartingPoint'!$C$28
Name OutsideInvest: '1-StartingPoint'!$D$35

Sheet Directions
B7: Step 1 - Enter info about your company in yellow shaded boxes below.
C9: Preparer Name | D9: Company Name | E9: Starting Month | F9: Starting Year
B12: Step 2 - Read the following instructions
C36: =IF(ISBLANK(E10),-10000,MONTH(DATEVALUE(E10&" 1"))) -> -10000
B38: =IF(Directions!$C$36>0,CHOOSE(Directions!$C$36,"January","February","March","April","May","June","July","August","September","October","November","December"),"Month 1") -> Month 1 | C38: =IF(Directions!$C$36+1>12,CHOOSE(Directions!$C$36+1-12,"January","February","March","April","May","June","July","August","September","October","November","December"),IF(Directions!$C$36<0,"Month 2",(CHOOSE(Directions!$C$36+1,"January","February","March","April","May","June","July","August","September","October","November","December")))) -> Month 2 | D38: =IF(Directions!$C$36+2>12,CHOOSE(Directions!$C$36+2-12,"January","February","March","April","May","June","July","August","September","October","November","December"),IF(Directions!$C$36<0,"Month 3",CHOOSE(Directions!$C$36+2,"January","February","March","April","May","June","July","August","September","October","November","December"))) -> Month 3 | E38: =IF(Directions!$C$36+3>12,CHOOSE(Directions!$C$36+3-12,"January","February","March","April","May","June","July","August","September","October","November","December"),IF(Directions!$C$36<0,"Month 4",CHOOSE(Directions!$C$36+3,"January","February","March","April","May","June","July","August","September","October","November","December"))) -> Month 4 | F38: =IF(Directions!$C$36+4>12,CHOOSE(Directions!$C$36+4-12,"January","February","March","April","May","June","July","August","September","October","November","December"),IF(Directions!$C$36<0,"Month 5",CHOOSE(Directions!$C$36+4,"January","February","March","April","May","June","July","August","September","October","November","December"))) -> Month 5 | G38: =IF(Directions!$C$36+5>12,CHOOSE(Directions!$C$36+5-12,"January","February","March","April","May","June","July","August","September","October","November","December"),IF(Directions!$C$36<0,"Month 6",CHOOSE(Directions!$C$36+5,"January","February","March","April","May","June","July","August","September","October","November","December"))) -> Month 6 | H38: =IF(Directions!$C$36+6>12,CHOOSE(Directions!$C$36+6-12,"January","February","March","April","May","June","July","August","September","October","November","December"),IF(Directions!$C$36<0,"Month 7",CHOOSE(Directions!$C$36+6,"January","February","March","April","May","June","July","August","September","October","November","December"))) -> Month 7 | I38: =IF(Directions!$C$36+7>12,CHOOSE(Directions!$C$36+7-12,"January","February","March","April","May","June","July","August","September","October","November","December"),IF(Directions!$C$36<0,"Month 8",CHOOSE(Directions!$C$36+7,"January","February","March","April","May","June","July","August","September","October","November","December"))) -> Month 8 | J38: =IF(Directions!$C$36+8>12,CHOOSE(Directions!$C$36+8-12,"January","February","March","April","May","June","July","August","September","October","November","December"),IF(Directions!$C$36<0,"Month 9",CHOOSE(Directions!$C$36+8,"January","February","March","April","May","June","July","August","September","October","November","December"))) -> Month 9 | K38: =IF(Directions!$C$36+9>12,CHOOSE(Directions!$C$36+9-12,"January","February","March","April","May","June","July","August","September","October","November","December"),IF(Directions!$C$36<0,"Month 10",CHOOSE(Directions!$C$36+9,"January","February","March","April","May","June","July","August","September","October","November","December"))) -> Month 10 | L38: =IF(Directions!$C$36+10>12,CHOOSE(Directions!$C$36+10-12,"January","February","March","April","May","June","July","August","September","October","November","December"),IF(Directions!$C$36<0,"Month 11",CHOOSE(Directions!$C$36+10,"January","February","March","April","May","June","July","August","September","October","November","December"))) -> Month 11 | M38: =IF(Directions!$C$36+11>12,CHOOSE(Directions!$C$36+11-12,"January","February","March","April","May","June","July","August","September","October","November","December"),IF(Directions!$C$36<0,"Month 12",CHOOSE(Directions!$C$36+11,"January","February","March","April","May","June","July","August","September","October","November","December"))) -> Month 12

Sheet 1-StartingPoint
B2: Start-up Expenses Year 1 (Starting Balance Sheet)
B4: Prepared By: | C4: Company Name:
B5: =IF(ISBLANK(Directions!C10),"Owner",Directions!C10) -> Owner | C5: =IF(ISBLANK(Directions!D10),"Company 1",Directions!D10) -> Company 1
B7: Fixed Assets | C7: Amount | D7: Depreciation (years) | E7: Notes
B9: Real Estate-Land | D9: Not Depreciated
B10: Real Estate-Buildings | D10: 20
B11: Leasehold Improvements | D11: 7
B12: Equipment | D12: 7
B13: Furniture and Fixtures | D13: 5
B14: Vehicles | D14: 5
B15: Other | D15: 5
B16: Total Fixed Assets | C16: =SUM(C9:C15) -> 0
B18: Operating Capital | C18: Amount | D18: Notes
B19: Pre-Opening Salaries and Wages
B20: Prepaid Insurance Premiums
B21: Inventory
B22: Legal and Accounting Fees
B23: Rent Deposits
B24: Utility Deposits
B25: Supplies
B26: Advertising and Promotions
B27: Licenses
B28: Other Initial Start-Up Costs
B29: Working Capital (Cash On Hand)
B30: Total Operating Capital | C30: =SUM(C19:C29) -> 0
B31: Total Required Funds | C31: =C16+C30 -> 0
B33: Sources of Funding | C33: Percentage | D33: Totals | E33: Loan Rate | F33: Term in Months | G33: Monthly Payments | H33: Notes
B34: Owner's Equity | C34: =IF($C$31=0,0,D34/$C$31) -> 0
B35: Outside Investors | C35: =IF($C$31=0,0,D35/$C$31) -> 0
B36: Additional Loans or Debt
B37: Commercial Loan | C37: =IF($C$31=0,0,D37/$C$31) -> 0 | E37: 0.09 | F37: 84 | G37: =PMT(E37/12,F37,-D37) -> 0
B38: Commercial Mortgage | C38: =IF($C$31=0,0,D38/$C$31) -> 0 | E38: 0.09 | F38: 240 | G38: =PMT(E38/12,F38,-D38) -> 0 | J38: See Loan Amortization & Depreciation Schedule
B39: Credit Card Debt | C39: =IF($C$31=0,0,D39/$C$31) -> 0 | E39: 0.07 | F39: 60 | G39: =PMT(E39/12,F39,-D39) -> 0
B40: Vehicle Loans | C40: =IF($C$31=0,0,D40/$C$31) -> 0 | E40: 0.06 | F40: 48 | G40: =PMT(E40/12,F40,-D40) -> 0
B41: Other Bank Debt | C41: =IF($C$31=0,0,D41/$C$31) -> 0 | E41: 0.05 | F41: 36 | G41: =PMT(E41/12,F41,-D41) -> 0
B42: Total Sources of Funding | C42: =IF($C$31=0,0,D42/$C$31) -> 0 | D42: =SUM(D34:D41) -> 0 | E42: Cell D 42 must equal cell C31 | G42: =SUM(G37:G41) -> 0
B43: Total Funding Needed | D43: =C31-D42 -> 0 | E43: =IF(D43>0,"You require more funding (Not Balanced)",IF(D43<0,"Your funding exceeds your needs (Not Balanced)","You are fully funded (Balanced)")) -> You are fully funded (Balanced)
B46: Existing Businesses ONLY -- Calculating Cash on Hand
B47: Cash | C47: 0
B48: + Accounts Receivable | C48: 0
...

Sheet 2a-PayrollYear1
B2: Payroll Year 1
B4: Prepared By: | C4: Company Name:
B5: =IF(ISBLANK(Directions!C10),"Owner",Directions!C10) -> Owner | C5: =IF(ISBLANK(Directions!D10),"Company 1",Directions!D10) -> Company 1
A7: Employee Types | B7: Number of Owners /Employees | C7: Average Hourly Pay (to 2 decimal places, ex. $15.23) | D7: Estimated Hrs./Week (per person) | E7: Estimated Pay/Month (Total) | F7: =Directions!B38 -> Month 1 | G7: =Directions!C38 -> Month 2 | H7: =Directions!D38 -> Month 3 | I7: =Directions!E38 -> Month 4 | J7: =Directions!F38 -> Month 5 | K7: =Directions!G38 -> Month 6 | L7: =Directions!H38 -> Month 7 | M7: =Directions!I38 -> Month 8 | ... Q7: =Directions!M38 -> Month 12 | R7: Annual Totals
A8: Founder (You) | B8: 1 | C8: 38.46 | D8: 40 | E8: =(C8*D8*B8)*52/12 -> 6666.4 | F8: 0 | G8: 0 | H8: 0 | I8: 3000 | J8: 4000 | K8: 5000 | L8: 6000 | M8: 6000 | N8: 6667 | O8: 6667 | P8: 6667 | Q8: 6667 | R8: =SUM(F8:Q8) -> 50668
A9: Sales Representatives | B9: 0 | C9: 25 | D9: 40 | E9: =(C9*D9*B9)*52/12 -> 0 | F9: =E9 -> 0 | G9: =F9 -> 0 | H9: =G9 -> 0 | I9: =H9 -> 0 | J9: =I9 -> 0 | K9: =J9 -> 0 | L9: =K9 -> 0 | M9: =L9 -> 0 | ... Q9: =P9 -> 0 | R9: =SUM(F9:Q9) -> 0
A10: Account Executives | B10: 0 | C10: 28.85 | D10: 40 | E10: =(C10*D10*B10)*52/12 -> 0 | F10: =E10 -> 0 | G10: =F10 -> 0 | H10: =G10 -> 0 | I10: =H10 -> 0 | J10: =I10 -> 0 | K10: =J10 -> 0 | L10: =K10 -> 0 | M10: =L10 -> 0 | ... Q10: =P10 -> 0 | R10: =SUM(F10:Q10) -> 0
A11: Independent Contractors | B11: 0 | E11: =(C11*D11*B11)*52/12 -> 0 | F11: =E11 -> 0 | G11: =F11 -> 0 | H11: =G11 -> 0 | I11: =H11 -> 0 | J11: =I11 -> 0 | K11: =J11 -> 0 | L11: =K11 -> 0 | M11: =L11 -> 0 | ... Q11: =P11 -> 0 | R11: =SUM(F11:Q11) -> 0
A12: Total Salaries and Wages | B12: =SUM(B8:B11) -> 1 | C12: =SUM(C8:C11) -> 92.31 | D12: =SUM(D8:D11) -> 120 | E12: =SUM(E8:E11) -> 6666.4 | F12: =SUM(F8:F11) -> 0 | G12: =SUM(G8:G11) -> 0 | H12: =SUM(H8:H11) -> 0 | I12: =SUM(I8:I11) -> 3000 | ... R12: =SUM(R8:R11) -> 50668
A14: Payroll Taxes and Benefits | B14: Wage Base Limit | C14: Percentage of Salary/Wage | E14: Estimated Taxes & Benefits/Month (Total) | F14: ='3a-SalesForecastYear1'!C16 -> Month 1 | G14: ='3a-SalesForecastYear1'!D16 -> Month 2 | H14: ='3a-SalesForecastYear1'!E16 -> Month 3 | I14: ='3a-SalesForecastYear1'!F16 -> Month 4 | J14: ='3a-SalesForecastYear1'!G16 -> Month 5 | K14: ='3a-SalesForecastYear1'!H16 -> Month 6 | L14: ='3a-SalesForecastYear1'!I16 -> Month 7 | M14: ='3a-SalesForecastYear1'!J16 -> Month 8 | ... R14: ='3a-SalesForecastYear1'!O16 -> Annual Totals
A15: Social Security | B15: 137700 | C15: 0.062 | E15: =(E$8+E$9+E$10)*$C$15 -> 413.3168 | F15: =(F$8+F$9+F$10)*$C$15 -> 0 | G15: =(G$8+G$9+G$10)*$C$15 -> 0 | H15: =(H$8+H$9+H$10)*$C$15 -> 0 | I15: =(I$8+I$9+I$10)*$C$15 -> 186 | J15: =(J$8+J$9+J$10)*$C$15 -> 248 | K15: =(K$8+K$9+K$10)*$C$15 -> 310 | L15: =(L$8+L$9+L$10)*$C$15 -> 372 | ... Q15: =(Q$8+Q$9+Q$10)*$C$15 -> 413.354 | R15: =SUM(F15:Q15) -> 3141.416
A16: Medicare | B16: -- | C16: 0.0145 | E16: =(E$8+E$9+E$10)*$C$16 -> 96.6628 | F16: =(F$8+F$9+F$10)*$C$16 -> 0 | G16: =(G$8+G$9+G$10)*$C$16 -> 0 | H16: =(H$8+H$9+H$10)*$C$16 -> 0 | I16: =(I$8+I$9+I$10)*$C$16 -> 43.5 | J16: =(J$8+J$9+J$10)*$C$16 -> 58 | K16: =(K$8+K$9+K$10)*$C$16 -> 72.5 | L16: =(L$8+L$9+L$10)*$C$16 -> 87 | ... Q16: =(Q$8+Q$9+Q$10)*$C$16 -> 96.6715 | R16: =SUM(F16:Q16) -> 734.686
A17: Federal Unemployment Tax (FUTA) | B17: 7000 | C17: 0.006 | E17: =+$B$12*B17*C17/12 -> 3.5 | F17: =E17 -> 3.5 | G17: =F17 -> 3.5 | H17: =G17 -> 3.5 | I17: =H17 -> 3.5 | J17: =I17 -> 3.5 | K17: =J17 -> 3.5 | L17: =K17 -> 3.5 | M17: =L17 -> 3.5 | ... Q17: =P17 -> 3.5 | R17: =SUM(F17:Q17) -> 42
A18: State Unemployment Tax (SUTA) | B18: 7000 | C18: 0.0345 | E18: =+$B$12*B18*C18/12 -> 20.125 | F18: =E18 -> 20.125 | G18: =F18 -> 20.125 | H18: =G18 -> 20.125 | I18: =H18 -> 20.125 | J18: =I18 -> 20.125 | K18: =J18 -> 20.125 | L18: =K18 -> 20.125 | M18: =L18 -> 20.125 | ... Q18: =P18 -> 20.125 | R18: =SUM(F18:Q18) -> 241.5
A19: Employee Pension Programs | B19: -- | C19: 0 | D19: ed | E19: =($E$8+$E$9+$E$10)*C19 -> 0 | F19: =E19 -> 0 | G19: =F19 -> 0 | H19: =G19 -> 0 | I19: =H19 -> 0 | J19: =I19 -> 0 | K19: =J19 -> 0 | L19: =K19 -> 0 | M19: =L19 -> 0 | ... Q19: =P19 -> 0 | R19: =SUM(F19:Q19) -> 0
A20: Worker's Compensation | B20: -- | C20: 0 | E20: =($E$8+$E$9+$E$10)*C20 -> 0 | F20: =E20 -> 0 | G20: =F20 -> 0 | H20: =G20 -> 0 | I20: =H20 -> 0 | J20: =I20 -> 0 | K20: =J20 -> 0 | L20: =K20 -> 0 | M20: =L20 -> 0 | ... Q20: =P20 -> 0 | R20: =SUM(F20:Q20) -> 0
A21: Employee Health Insurance | B21: -- | C21: 0 | E21: =($E$8+$E$9+$E$10)*C21 -> 0 | F21: =E21 -> 0 | G21: =F21 -> 0 | H21: =G21 -> 0 | I21: =H21 -> 0 | J21: =I21 -> 0 | K21: =J21 -> 0 | L21: =K21 -> 0 | M21: =L21 -> 0 | ... Q21: =P21 -> 0 | R21: =SUM(F21:Q21) -> 0
A22: Other Employee Benefit Programs | B22: -- | C22: 0 | E22: =($E$8+$E$9+$E$10)*C22 -> 0 | F22: =E22 -> 0 | G22: =F22 -> 0 | H22: =G22 -> 0 | I22: =H22 -> 0 | J22: =I22 -> 0 | K22: =J22 -> 0 | L22: =K22 -> 0 | M22: =L22 -> 0 | ... Q22: =P22 -> 0 | R22: =SUM(F22:Q22) -> 0
A23: Total Payroll Taxes and Benefits | C23: =SUM(C15:C22) -> 0.117 | E23: =SUM(E15:E22) -> 533.6046 | F23: =SUM(F15:F22) -> 23.625 | G23: =SUM(G15:G22) -> 23.625 | H23: =SUM(H15:H22) -> 23.625 | I23: =SUM(I15:I22) -> 253.125 | J23: =SUM(J15:J22) -> 329.625 | K23: =SUM(K15:K22) -> 406.125 | L23: =SUM(L15:L22) -> 482.625 | ... R23: =SUM(R15:R22) -> 4159.602
A25: Total Salaries and Related Expenses | E25: =E12+E23 -> 7200.0046 | F25: =F12+F23 -> 23.625 | G25: =G12+G23 -> 23.625 | H25: =H12+H23 -> 23.625 | I25: =I12+I23 -> 3253.125 | J25: =J12+J23 -> 4329.625 | K25: =K12+K23 -> 5406.125 | L25: =L12+L23 -> 6482.625 | ... R25: =R12+R23 -> 54827.602

Sheet 2b-PayrollYrs1-3
B2: Payroll Years 1-3
B4: Prepared By: | C4: Company Name:
B5: =IF(ISBLANK(Directions!C10),"Owner",Directions!C10) -> Owner | C5: =IF(ISBLANK(Directions!D10),"Company 1",Directions!D10) -> Company 1
B8: Employee Types | C8: Year 1 Totals | D8: Growth Rate 1 to 2 | E8: =IF(Directions!G7>0,Directions!G7+1,"Second Year") -> Second Year | F8: Growth Rate 2 to 3 | G8: =IF(Directions!G7>0,Directions!G7+2,"Third Year") -> Third Year
B9: Owner(s) | C9: ='2a-PayrollYear1'!R8 -> 50668 | D9: 0.2 | E9: =C9*D9+C9 -> 60801.6 | F9: 0.3 | G9: =E9*F9+E9 -> 79042.08
B10: Full-Time Employees | C10: ='2a-PayrollYear1'!R9 -> 0 | D10: 0.2 | E10: =C10*D10+C10 -> 0 | F10: 0.3 | G10: =E10*F10+E10 -> 0
B11: Part-Time Employees | C11: ='2a-PayrollYear1'!R10 -> 0 | D11: 0.1 | E11: =C11*D11+C11 -> 0 | F11: 0.3 | G11: =E11*F11+E11 -> 0
B12: Independent Contractors | C12: ='2a-PayrollYear1'!R11 -> 0 | D12: 0.03 | E12: =C12*D12+C12 -> 0 | F12: 0.03 | G12: =E12*F12+E12 -> 0
B13: Total Salaries and Wages | C13: =SUM(C9:C12) -> 50668 | E13: =SUM(E9:E12) -> 60801.6 | G13: =SUM(G9:G12) -> 79042.08
B15: Payroll Taxes and Benefits
B16: Social Security | C16: ='2a-PayrollYear1'!R15 -> 3141.416 | D16: 0.2 | E16: =C16*D16+C16 -> 3769.6992 | F16: 0.3 | G16: =E16*F16+E16 -> 4900.609
B17: Medicare | C17: ='2a-PayrollYear1'!R16 -> 734.686 | D17: 0.2 | E17: =C17*D17+C17 -> 881.6232 | F17: 0.3 | G17: =E17*F17+E17 -> 1146.1102
B18: Federal Unemployment Tax (FUTA) | C18: ='2a-PayrollYear1'!R17 -> 42 | D18: 0.2 | E18: =C18*D18+C18 -> 50.4 | F18: 0.3 | G18: =E18*F18+E18 -> 65.52
B19: State Unemployment Tax (SUTA) | C19: ='2a-PayrollYear1'!R18 -> 241.5 | D19: 0.2 | E19: =C19*D19+C19 -> 289.8 | F19: 0.3 | G19: =E19*F19+E19 -> 376.74
B20: Employee Pension Programs | C20: ='2a-PayrollYear1'!R19 -> 0 | D20: 0 | E20: =C20*D20+C20 -> 0 | F20: 0 | G20: =E20*F20+E20 -> 0
B21: Worker's Compensation | C21: ='2a-PayrollYear1'!R20 -> 0 | D21: 0.03 | E21: =C21*D21+C21 -> 0 | F21: 0.03 | G21: =E21*F21+E21 -> 0
B22: Employee Health Insurance | C22: ='2a-PayrollYear1'!R21 -> 0 | D22: 0.03 | E22: =C22*D22+C22 -> 0 | F22: 0.03 | G22: =E22*F22+E22 -> 0
B23: Other Employee Benefit Programs | C23: ='2a-PayrollYear1'!R22 -> 0 | D23: 0.1 | E23: =C23*D23+C23 -> 0 | F23: 0.1 | G23: =E23*F23+E23 -> 0
B24: Total Payroll Taxes and Benefits | C24: =SUM(C16:C23) -> 4159.602 | E24: =SUM(E16:E23) -> 4991.5224 | G24: =SUM(G16:G23) -> 6488.9791
B26: Total Salaries and Related Expenses | C26: =SUM(C13+C24) -> 54827.602 | E26: =SUM(E13+E24) -> 65793.122 | G26: =SUM(G13+G24) -> 85531.059

Sheet 3a-SalesForecastYear1
B2: Sales Forecast Year 1 Q1 | D2: Q2 | E2: Q3 | F2: Q4
B3: Monthly Growth Rate by Qtr Yr1 | C3: 1 | D3: 0.5 | E3: 0.5 | F3: 0.5
B4: Prepared By: | C4: Company Name:
B5: =IF(ISBLANK(Directions!C10),"Owner",Directions!C10) -> Owner | C5: =IF(ISBLANK(Directions!D10),"Company 1",Directions!D10) -> Company 1
B7: Complete This Chart First:
B8: Product Lines | C8: Units | D8: Sales Price Per Unit | E8: COGS Per Unit | F8: Margin Per Unit
B9: Number of Contractors | C9: 1 | D9: {='4-AdditionalInputs'!C56} -> 540 | E9: {='4-AdditionalInputs'!C65} -> 180 | F9: =D9-E9 -> 360
B10: Immediate Revenue (70%) | C10: 1 | D10: ='4-AdditionalInputs'!C56*'4-AdditionalInputs'!C59 -> 378 | E10: {='4-AdditionalInputs'!C65} -> 180 | F10: =D10-E10 -> 198
B11: Deferred Revenue - 1 Month (20%) | C11: 1 | D11: ='4-AdditionalInputs'!C56*'4-AdditionalInputs'!C60 -> 108 | E11: 0 | F11: =D11-E11 -> 108
B12: Deferred Revenue - 6 Months (10%) | C12: 1 | D12: ='4-AdditionalInputs'!C56*'4-AdditionalInputs'!C61 -> 54 | E12: 0 | F12: =D12-E12 -> 54
F13: =D13-E13 -> 0
F14: =D14-E14 -> 0
B16: Product Lines | C16: ='2a-PayrollYear1'!F7 -> Month 1 | D16: ='2a-PayrollYear1'!G7 -> Month 2 | E16: ='2a-PayrollYear1'!H7 -> Month 3 | F16: ='2a-PayrollYear1'!I7 -> Month 4 | G16: ='2a-PayrollYear1'!J7 -> Month 5 | H16: ='2a-PayrollYear1'!K7 -> Month 6 | I16: ='2a-PayrollYear1'!L7 -> Month 7 | J16: ='2a-PayrollYear1'!M7 -> Month 8 | ... N16: ='2a-PayrollYear1'!Q7 -> Month 12 | O16: Annual Totals | P16: Category Breakdown | Q16: Category / Total
B17: =IF(ISBLANK(B9),"Product 1",B9) -> Number of Contractors
B18: =IF(ISBLANK(C9),"Units Sold",Unit1&" Sold") -> 1 Sold | C18: 18 | D18: 18 | E18: 18 | F18: 35 | G18: 35 | H18: 35 | I18: 53 | J18: 53 | K18: 70 | L18: 70 | M18: 88 | N18: 106 | O18: =SUM(C18:N18) -> 599 | Q18: =IF($O$52=0,0,O18/$O$52) -> 0.32378378
B19: Total Sales | C19: =$D$9*C18 -> 9720 | D19: =$D$9*D18 -> 9720 | E19: =$D$9*E18 -> 9720 | F19: =$D$9*F18 -> 18900 | G19: =$D$9*G18 -> 18900 | H19: =$D$9*H18 -> 18900 | I19: =$D$9*I18 -> 28620 | J19: =$D$9*J18 -> 28620 | ... N19: =$D$9*N18 -> 57240 | O19: =SUM(C19:N19) -> 323460 | P19: =(P20+P21) -> 1 | Q19: =IF($O$53=0,0,O19/$O$53) -> 0.52877825
B20: Total COGS | C20: =$E$9*C18 -> 3240 | D20: =$E$9*D18 -> 3240 | E20: =$E$9*E18 -> 3240 | F20: =$E$9*F18 -> 6300 | G20: =$E$9*G18 -> 6300 | H20: =$E$9*H18 -> 6300 | I20: =$E$9*I18 -> 9540 | J20: =$E$9*J18 -> 9540 | ... N20: =$E$9*N18 -> 19080 | O20: =SUM(C20:N20) -> 107820 | P20: =IF(O19=0,0,O20/O19) -> 0.33333333 | Q20: =IF($O$54=0,0,O20/$O$54) -> 0.5
B21: Total Margin | C21: =C19-C20 -> 6480 | D21: =D19-D20 -> 6480 | E21: =E19-E20 -> 6480 | F21: =F19-F20 -> 12600 | G21: =G19-G20 -> 12600 | H21: =H19-H20 -> 12600 | I21: =I19-I20 -> 19080 | J21: =J19-J20 -> 19080 | ... N21: =N19-N20 -> 38160 | O21: =SUM(C21:N21) -> 215640 | P21: =IF(O19=0,0,O21/O19) -> 0.66666667 | Q21: =IF($O$55=0,0,O21/$O$55) -> 0.54444646
B23: =IF(ISBLANK(B10),"Product 2",B10) -> Immediate Revenue (70%)
B24: =IF(ISBLANK(C10),"Units Sold",Unit2&" Sold") -> 1 Sold | C24: {=C18} -> 18 | D24: {=D18} -> 18 | E24: {=E18} -> 18 | F24: {=F18} -> 35 | G24: {=G18} -> 35 | H24: {=H18} -> 35 | I24: {=I18} -> 53 | J24: {=J18} -> 53 | ... N24: {=N18} -> 106 | O24: =SUM(C24:N24) -> 599 | Q24: =IF($O$52=0,0,O24/$O$52) -> 0.32378378
B25: Total Sales | C25: =$D$10*C24 -> 6804 | D25: =$D$10*D24 -> 6804 | E25: =$D$10*E24 -> 6804 | F25: =$D$10*F24 -> 13230 | G25: =$D$10*G24 -> 13230 | H25: =$D$10*H24 -> 13230 | I25: =$D$10*I24 -> 20034 | J25: =$D$10*J24 -> 20034 | ... N25: =$D$10*N24 -> 40068 | O25: =SUM(C25:N25) -> 226422 | P25: =(P26+P27) -> 1 | Q25: =IF($O$53=0,0,O25/$O$53) -> 0.37014477
B26: Total COGS | C26: =$E$10*C24 -> 3240 | D26: =$E$10*D24 -> 3240 | E26: =$E$10*E24 -> 3240 | F26: =$E$10*F24 -> 6300 | G26: =$E$10*G24 -> 6300 | H26: =$E$10*H24 -> 6300 | I26: =$E$10*I24 -> 9540 | J26: =$E$10*J24 -> 9540 | ... N26: =$E$10*N24 -> 19080 | O26: =SUM(C26:N26) -> 107820 | P26: =IF(O25=0,0,O26/O25) -> 0.47619048 | Q26: =IF($O$54=0,0,O26/$O$54) -> 0.5
B27: Margin | C27: =C25-C26 -> 3564 | D27: =D25-D26 -> 3564 | E27: =E25-E26 -> 3564 | F27: =F25-F26 -> 6930 | G27: =G25-G26 -> 6930 | H27: =H25-H26 -> 6930 | I27: =I25-I26 -> 10494 | J27: =J25-J26 -> 10494 | ... N27: =N25-N26 -> 20988 | O27: =SUM(C27:N27) -> 118602 | P27: =IF(O25=0,0,O27/O25) -> 0.52380952 | Q27: =IF($O$55=0,0,O27/$O$55) -> 0.29944556
B29: =IF(ISBLANK(B11),"Product 3",B11) -> Deferred Revenue - 1 Month (20%)
B30: =IF(ISBLANK(C11),"Units Sold",Unit3&" Sold") -> 1 Sold | C30: 0 | D30: {=C18} -> 18 | E30: {=D18} -> 18 | F30: {=E18} -> 18 | G30: {=F18} -> 35 | H30: {=G18} -> 35 | I30: {=H18} -> 35 | J30: {=I18} -> 53 | K30: {=J18} -> 53 | ... N30: {=M18} -> 88 | O30: =SUM(C30:N30) -> 493 | Q30: =IF($O$52=0,0,O30/$O$52) -> 0.26648649
B31: Total Sales | C31: =$D$11*C30 -> 0 | D31: =$D$11*D30 -> 1944 | E31: =$D$11*E30 -> 1944 | F31: =$D$11*F30 -> 1944 | G31: =$D$11*G30 -> 3780 | H31: =$D$11*H30 -> 3780 | I31: =$D$11*I30 -> 3780 | J31: =$D$11*J30 -> 5724 | ... N31: =$D$11*N30 -> 9504 | O31: =SUM(C31:N31) -> 53244 | P31: =(P32+P33) -> 1 | Q31: =IF($O$53=0,0,O31/$O$53) -> 0.08704096
B32: Total COGS | C32: =$E$11*C30 -> 0 | D32: =$E$11*D30 -> 0 | E32: =$E$11*E30 -> 0 | F32: =$E$11*F30 -> 0 | G32: =$E$11*G30 -> 0 | H32: =$E$11*H30 -> 0 | I32: =$E$11*I30 -> 0 | J32: =$E$11*J30 -> 0 | ... N32: =$E$11*N30 -> 0 | O32: =SUM(C32:N32) -> 0 | P32: =IF(O31=0,0,O32/O31) -> 0 | Q32: =IF($O$54=0,0,O32/$O$54) -> 0
B33: Margin | C33: =C31-C32 -> 0 | D33: =D31-D32 -> 1944 | E33: =E31-E32 -> 1944 | F33: =F31-F32 -> 1944 | G33: =G31-G32 -> 3780 | H33: =H31-H32 -> 3780 | I33: =I31-I32 -> 3780 | J33: =J31-J32 -> 5724 | ... N33: =N31-N32 -> 9504 | O33: =SUM(C33:N33) -> 53244 | P33: =IF(O31=0,0,O33/O31) -> 1 | Q33: =IF($O$55=0,0,O33/$O$55) -> 0.1344301
B35: =IF(ISBLANK(B12),"Product 4",B12) -> Deferred Revenue - 6 Months (10%)
B36: =IF(ISBLANK(C12),"Units Sold",Unit4&" Sold") -> 1 Sold | C36: 0 | D36: 0 | E36: 0 | F36: 0 | G36: 0 | H36: 0 | I36: {=C18} -> 18 | J36: {=D18} -> 18 | K36: {=E18} -> 18 | L36: {=F18} -> 35 | M36: {=G18} -> 35 | N36: {=H18} -> 35 | O36: =SUM(C36:N36) -> 159 | Q36: =IF($O$52=0,0,O36/$O$52) -> 0.085945946
B37: Total Sales | C37: =$D$12*C36 -> 0 | D37: =$D$12*D36 -> 0 | E37: =$D$12*E36 -> 0 | F37: =$D$12*F36 -> 0 | G37: =$D$12*G36 -> 0 | H37: =$D$12*H36 -> 0 | I37: =$D$12*I36 -> 972 | J37: =$D$12*J36 -> 972 | ... N37: =$D$12*N36 -> 1890 | O37: =SUM(C37:N37) -> 8586 | P37: =(P38+P39) -> 1 | Q37: =IF($O$53=0,0,O37/$O$53) -> 0.014036017
B38: Total COGS | C38: =$E$12*C36 -> 0 | D38: =$E$12*D36 -> 0 | E38: =$E$12*E36 -> 0 | F38: =$E$12*F36 -> 0 | G38: =$E$12*G36 -> 0 | H38: =$E$12*H36 -> 0 | I38: =$E$12*I36 -> 0 | J38: =$E$12*J36 -> 0 | ... N38: =$E$12*N36 -> 0 | O38: =SUM(C38:N38) -> 0 | P38: =IF(O37=0,0,O38/O37) -> 0 | Q38: =IF($O$54=0,0,O38/$O$54) -> 0
B39: Margin | C39: =C37-C38 -> 0 | D39: =D37-D38 -> 0 | E39: =E37-E38 -> 0 | F39: =F37-F38 -> 0 | G39: =G37-G38 -> 0 | H39: =H37-H38 -> 0 | I39: =I37-I38 -> 972 | J39: =J37-J38 -> 972 | ... N39: =N37-N38 -> 1890 | O39: =SUM(C39:N39) -> 8586 | P39: =IF(O37=0,0,O39/O37) -> 1 | Q39: =IF($O$55=0,0,O39/$O$55) -> 0.021677877
B41: =IF(ISBLANK(B13),"Product 5",B13) -> Product 5
B42: =IF(ISBLANK(C13),"Units Sold",Unit5&" Sold") -> Units Sold | D42: =C42+C42*$C$3 -> 0 | E42: =D42+D42*$C$3 -> 0 | F42: =E42+E42*$D$3 -> 0 | G42: =F42+F42*$D$3 -> 0 | H42: =G42+G42*$D$3 -> 0 | I42: =H42+H42*$E$3 -> 0 | J42: =I42+I42*$E$3 -> 0 | K42: =J42+J42*$E$3 -> 0 | L42: =K42+K42*$F$3 -> 0 | M42: =L42+L42*$F$3 -> 0 | N42: =M42+M42*$F$3 -> 0 | O42: =SUM(C42:N42) -> 0 | Q42: =IF($O$52=0,0,O42/$O$52) -> 0
B43: Total Sales | C43: =$D$13*C42 -> 0 | D43: =$D$13*D42 -> 0 | E43: =$D$13*E42 -> 0 | F43: =$D$13*F42 -> 0 | G43: =$D$13*G42 -> 0 | H43: =$D$13*H42 -> 0 | I43: =$D$13*I42 -> 0 | J43: =$D$13*J42 -> 0 | ... N43: =$D$13*N42 -> 0 | O43: =SUM(C43:N43) -> 0 | P43: =(P44+P45) -> 0 | Q43: =IF($O$53=0,0,O43/$O$53) -> 0
B44: Total COGS | C44: =$E$13*C42 -> 0 | D44: =$E$13*D42 -> 0 | E44: =$E$13*E42 -> 0 | F44: =$E$13*F42 -> 0 | G44: =$E$13*G42 -> 0 | H44: =$E$13*H42 -> 0 | I44: =$E$13*I42 -> 0 | J44: =$E$13*J42 -> 0 | ... N44: =$E$13*N42 -> 0 | O44: =SUM(C44:N44) -> 0 | P44: =IF(O43=0,0,O44/O43) -> 0 | Q44: =IF($O$54=0,0,O44/$O$54) -> 0
B45: Margin | C45: =C43-C44 -> 0 | D45: =D43-D44 -> 0 | E45: =E43-E44 -> 0 | F45: =F43-F44 -> 0 | G45: =G43-G44 -> 0 | H45: =H43-H44 -> 0 | I45: =I43-I44 -> 0 | J45: =J43-J44 -> 0 | ... N45: =N43-N44 -> 0 | O45: =SUM(C45:N45) -> 0 | P45: =IF(O43=0,0,O45/O43) -> 0 | Q45: =IF($O$55=0,0,O45/$O$55) -> 0
B47: =IF(ISBLANK(B14),"Product 6",B14) -> Product 6
B48: =IF(ISBLANK(C14),"Units Sold",Unit6&" Sold") -> Units Sold | D48: =C48+C48*$C$3 -> 0 | E48: =D48+D48*$C$3 -> 0 | F48: =E48+E48*$D$3 -> 0 | G48: =F48+F48*$D$3 -> 0 | H48: =G48+G48*$D$3 -> 0 | I48: =H48+H48*$E$3 -> 0 | J48: =I48+I48*$E$3 -> 0 | K48: =J48+J48*$E$3 -> 0 | L48: =K48+K48*$F$3 -> 0 | M48: =L48+L48*$F$3 -> 0 | N48: =M48+M48*$F$3 -> 0 | O48: =SUM(C48:N48) -> 0 | Q48: =IF($O$52=0,0,O48/$O$52) -> 0
...

Sheet 3b-SalesForecastYrs1-3
B2: Sales Forecast Year 1-3
B4: Prepared by: | C4: Company Name:
B5: =IF(ISBLANK(Directions!C10),"Owner",Directions!C10) -> Owner | C5: =IF(ISBLANK(Directions!D10),"Company 1",Directions!D10) -> Company 1
B7: Monthly Growth Rate Year 2 | C7: 0.03
B8: Monthly Growth Rate Year 3 | C8: 0.02
A10: Product Lines | B10: Year 1 Totals | C10: ='2a-PayrollYear1'!F7 -> Month 1 | D10: ='2a-PayrollYear1'!G7 -> Month 2 | E10: ='2a-PayrollYear1'!H7 -> Month 3 | F10: ='2a-PayrollYear1'!I7 -> Month 4 | G10: ='2a-PayrollYear1'!J7 -> Month 5 | H10: ='2a-PayrollYear1'!K7 -> Month 6 | I10: ='2a-PayrollYear1'!L7 -> Month 7 | J10: ='2a-PayrollYear1'!M7 -> Month 8 | ... N10: ='2a-PayrollYear1'!Q7 -> Month 12 | O10: Year 2 Totals | P10: Category Breakdown | Q10: Category / Total | R10: ='2a-PayrollYear1'!F7 -> Month 1 | S10: ='2a-PayrollYear1'!G7 -> Month 2 | T10: ='2a-PayrollYear1'!H7 -> Month 3 | U10: ='2a-PayrollYear1'!I7 -> Month 4 | V10: ='2a-PayrollYear1'!J7 -> Month 5 | W10: ='2a-PayrollYear1'!K7 -> Month 6 | X10: ='2a-PayrollYear1'!L7 -> Month 7 | Y10: ='2a-PayrollYear1'!M7 -> Month 8 | ... AC10: ='2a-PayrollYear1'!Q7 -> Month 12 | AD10: Year 3 Totals | AE10: Category Breakdown | AF10: Category / Total
A11: ='3a-SalesForecastYear1'!B17 -> Number of Contractors
A12: =Unit1&" Sold" -> 1 Sold | B12: =Unit1_Annual -> 599 | C12: ='3a-SalesForecastYear1'!N18 -> 106 | D12: =C12+C12*$C$7 -> 109.18 | E12: =D12+D12*$C$7 -> 112.4554 | F12: =E12+E12*$C$7 -> 115.82906 | G12: =F12+F12*$C$7 -> 119.30393 | H12: =G12+G12*$C$7 -> 122.88305 | I12: =H12+H12*$C$7 -> 126.56954 | J12: =I12+I12*$C$7 -> 130.36663 | K12: =J12+J12*$C$7 -> 134.27763 | ... N12: =M12+M12*$C$7 -> 146.72879 | O12: =SUM(C12:N12) -> 1504.3551 | Q12: =IF($O$46=0,0,O12/$O$46) -> 0.31641791 | R12: =N12 -> 146.72879 | S12: =R12+R12*$C$8 -> 149.66337 | T12: =S12+S12*$C$8 -> 152.65663 | U12: =T12+T12*$C$8 -> 155.70977 | V12: =U12+U12*$C$8 -> 158.82396 | W12: =V12+V12*$C$8 -> 162.00044 | X12: =W12+W12*$C$8 -> 165.24045 | Y12: =X12+X12*$C$8 -> 168.54526 | Z12: =Y12+Y12*$C$8 -> 171.91616 | ... AC12: =AB12+AB12*$C$8 -> 182.43881 | AD12: =SUM(R12:AC12) -> 1967.9397 | AF12: =IF($AD$46=0,0,AD12/$AD$46) -> 0.31641791
A13: Total Sales | B13: =Category1_Annual_Sales -> 323460 | C13: =+C12*'3a-SalesForecastYear1'!$D$9 -> 57240 | D13: =+D12*'3a-SalesForecastYear1'!$D$9 -> 58957.2 | E13: =+E12*'3a-SalesForecastYear1'!$D$9 -> 60725.916 | F13: =+F12*'3a-SalesForecastYear1'!$D$9 -> 62547.693 | G13: =+G12*'3a-SalesForecastYear1'!$D$9 -> 64424.124 | H13: =+H12*'3a-SalesForecastYear1'!$D$9 -> 66356.848 | I13: =+I12*'3a-SalesForecastYear1'!$D$9 -> 68347.553 | J13: =+J12*'3a-SalesForecastYear1'!$D$9 -> 70397.98 | ... N13: =+N12*'3a-SalesForecastYear1'!$D$9 -> 79233.547 | O13: =SUM(C13:N13) -> 812351.77 | P13: =(P14+P15) -> 1 | Q13: =IF($O$47=0,0,O13/$O$47) -> 0.52657725 | R13: =+R12*'3a-SalesForecastYear1'!$D$9 -> 79233.547 | S13: =+S12*'3a-SalesForecastYear1'!$D$9 -> 80818.218 | T13: =+T12*'3a-SalesForecastYear1'!$D$9 -> 82434.582 | U13: =+U12*'3a-SalesForecastYear1'!$D$9 -> 84083.274 | V13: =+V12*'3a-SalesForecastYear1'!$D$9 -> 85764.939 | W13: =+W12*'3a-SalesForecastYear1'!$D$9 -> 87480.238 | X13: =+X12*'3a-SalesForecastYear1'!$D$9 -> 89229.843 | Y13: =+Y12*'3a-SalesForecastYear1'!$D$9 -> 91014.44 | ... AC13: =+AC12*'3a-SalesForecastYear1'!$D$9 -> 98516.956 | AD13: =SUM(R13:AC13) -> 1062687.4 | AE13: =(AE14+AE15) -> 1 | AF13: =IF($AD$47=0,0,AD13/$AD$47) -> 0.52657725
A14: Total COGS | B14: ='3a-SalesForecastYear1'!O20 -> 107820 | C14: =+C12*'3a-SalesForecastYear1'!$E$9 -> 19080 | D14: =+D12*'3a-SalesForecastYear1'!$E$9 -> 19652.4 | E14: =+E12*'3a-SalesForecastYear1'!$E$9 -> 20241.972 | F14: =+F12*'3a-SalesForecastYear1'!$E$9 -> 20849.231 | G14: =+G12*'3a-SalesForecastYear1'!$E$9 -> 21474.708 | H14: =+H12*'3a-SalesForecastYear1'!$E$9 -> 22118.949 | I14: =+I12*'3a-SalesForecastYear1'!$E$9 -> 22782.518 | J14: =+J12*'3a-SalesForecastYear1'!$E$9 -> 23465.993 | ... N14: =+N12*'3a-SalesForecastYear1'!$E$9 -> 26411.182 | O14: =SUM(C14:N14) -> 270783.92 | P14: =IF(O13=0,0,O14/O13) -> 0.33333333 | Q14: =IF($O$48=0,0,O14/$O$48) -> 0.5 | R14: =+R12*'3a-SalesForecastYear1'!$E$9 -> 26411.182 | S14: =+S12*'3a-SalesForecastYear1'!$E$9 -> 26939.406 | T14: =+T12*'3a-SalesForecastYear1'!$E$9 -> 27478.194 | U14: =+U12*'3a-SalesForecastYear1'!$E$9 -> 28027.758 | V14: =+V12*'3a-SalesForecastYear1'!$E$9 -> 28588.313 | W14: =+W12*'3a-SalesForecastYear1'!$E$9 -> 29160.079 | X14: =+X12*'3a-SalesForecastYear1'!$E$9 -> 29743.281 | Y14: =+Y12*'3a-SalesForecastYear1'!$E$9 -> 30338.147 | ... AC14: =+AC12*'3a-SalesForecastYear1'!$E$9 -> 32838.985 | AD14: =SUM(R14:AC14) -> 354229.15 | AE14: =IF(AD13=0,0,AD14/AD13) -> 0.33333333 | AF14: =IF($AD$48=0,0,AD14/$AD$48) -> 0.5
A15: Total Margin | B15: ='3a-SalesForecastYear1'!O21 -> 215640 | C15: =C13-C14 -> 38160 | D15: =D13-D14 -> 39304.8 | E15: =E13-E14 -> 40483.944 | F15: =F13-F14 -> 41698.462 | G15: =G13-G14 -> 42949.416 | H15: =H13-H14 -> 44237.899 | I15: =I13-I14 -> 45565.036 | J15: =J13-J14 -> 46931.987 | ... N15: =N13-N14 -> 52822.365 | O15: =SUM(C15:N15) -> 541567.85 | P15: =IF(O13=0,0,O15/O13) -> 0.66666667 | Q15: =IF($O$49=0,0,O15/$O$49) -> 0.54095433 | R15: =R13-R14 -> 52822.365 | S15: =S13-S14 -> 53878.812 | T15: =T13-T14 -> 54956.388 | U15: =U13-U14 -> 56055.516 | V15: =V13-V14 -> 57176.626 | W15: =W13-W14 -> 58320.159 | X15: =X13-X14 -> 59486.562 | Y15: =Y13-Y14 -> 60676.293 | ... AC15: =AC13-AC14 -> 65677.971 | AD15: =SUM(R15:AC15) -> 708458.29 | AE15: =IF(AD13=0,0,AD15/AD13) -> 0.66666667 | AF15: =IF($AD$49=0,0,AD15/$AD$49) -> 0.54095433
A17: ='3a-SalesForecastYear1'!B23 -> Immediate Revenue (70%)
A18: =Unit2&" Sold" -> 1 Sold | B18: =Unit2_Annual -> 599 | C18: ='3a-SalesForecastYear1'!N24 -> 106 | D18: =C18+C18*$C$7 -> 109.18 | E18: =D18+D18*$C$7 -> 112.4554 | F18: =E18+E18*$C$7 -> 115.82906 | G18: =F18+F18*$C$7 -> 119.30393 | H18: =G18+G18*$C$7 -> 122.88305 | I18: =H18+H18*$C$7 -> 126.56954 | J18: =I18+I18*$C$7 -> 130.36663 | K18: =J18+J18*$C$7 -> 134.27763 | ... N18: =M18+M18*$C$7 -> 146.72879 | O18: =SUM(C18:N18) -> 1504.3551 | Q18: =IF($O$46=0,0,O18/$O$46) -> 0.31641791 | R18: =N18 -> 146.72879 | S18: =R18+R18*$C$8 -> 149.66337 | T18: =S18+S18*$C$8 -> 152.65663 | U18: =T18+T18*$C$8 -> 155.70977 | V18: =U18+U18*$C$8 -> 158.82396 | W18: =V18+V18*$C$8 -> 162.00044 | X18: =W18+W18*$C$8 -> 165.24045 | Y18: =X18+X18*$C$8 -> 168.54526 | Z18: =Y18+Y18*$C$8 -> 171.91616 | ... AC18: =AB18+AB18*$C$8 -> 182.43881 | AD18: =SUM(R18:AC18) -> 1967.9397 | AF18: =IF($AD$46=0,0,AD18/$AD$46) -> 0.31641791
A19: Total Sales | B19: =Category2_Annual_Sales -> 226422 | C19: =+C18*'3a-SalesForecastYear1'!$D$10 -> 40068 | D19: =+D18*'3a-SalesForecastYear1'!$D$10 -> 41270.04 | E19: =+E18*'3a-SalesForecastYear1'!$D$10 -> 42508.141 | F19: =+F18*'3a-SalesForecastYear1'!$D$10 -> 43783.385 | G19: =+G18*'3a-SalesForecastYear1'!$D$10 -> 45096.887 | H19: =+H18*'3a-SalesForecastYear1'!$D$10 -> 46449.794 | I19: =+I18*'3a-SalesForecastYear1'!$D$10 -> 47843.287 | J19: =+J18*'3a-SalesForecastYear1'!$D$10 -> 49278.586 | ... N19: =+N18*'3a-SalesForecastYear1'!$D$10 -> 55463.483 | O19: =SUM(C19:N19) -> 568646.24 | P19: =(P20+P21) -> 1 | Q19: =IF($O$47=0,0,O19/$O$47) -> 0.36860407 | R19: =+R18*'3a-SalesForecastYear1'!$D$10 -> 55463.483 | S19: =+S18*'3a-SalesForecastYear1'!$D$10 -> 56572.752 | T19: =+T18*'3a-SalesForecastYear1'!$D$10 -> 57704.207 | U19: =+U18*'3a-SalesForecastYear1'!$D$10 -> 58858.292 | V19: =+V18*'3a-SalesForecastYear1'!$D$10 -> 60035.457 | W19: =+W18*'3a-SalesForecastYear1'!$D$10 -> 61236.167 | X19: =+X18*'3a-SalesForecastYear1'!$D$10 -> 62460.89 | Y19: =+Y18*'3a-SalesForecastYear1'!$D$10 -> 63710.108 | ... AC19: =+AC18*'3a-SalesForecastYear1'!$D$10 -> 68961.869 | AD19: =SUM(R19:AC19) -> 743881.21 | AE19: =(AE20+AE21) -> 1 | AF19: =IF($AD$47=0,0,AD19/$AD$47) -> 0.36860407
A20: Total COGS | B20: ='3a-SalesForecastYear1'!O26 -> 107820 | C20: =+C18*'3a-SalesForecastYear1'!$E$10 -> 19080 | D20: =+D18*'3a-SalesForecastYear1'!$E$10 -> 19652.4 | E20: =+E18*'3a-SalesForecastYear1'!$E$10 -> 20241.972 | F20: =+F18*'3a-SalesForecastYear1'!$E$10 -> 20849.231 | G20: =+G18*'3a-SalesForecastYear1'!$E$10 -> 21474.708 | H20: =+H18*'3a-SalesForecastYear1'!$E$10 -> 22118.949 | I20: =+I18*'3a-SalesForecastYear1'!$E$10 -> 22782.518 | J20: =+J18*'3a-SalesForecastYear1'!$E$10 -> 23465.993 | ... N20: =+N18*'3a-SalesForecastYear1'!$E$10 -> 26411.182 | O20: =SUM(C20:N20) -> 270783.92 | P20: =IF(O19=0,0,O20/O19) -> 0.47619048 | Q20: =IF($O$48=0,0,O20/$O$48) -> 0.5 | R20: =+R18*'3a-SalesForecastYear1'!$E$10 -> 26411.182 | S20: =+S18*'3a-SalesForecastYear1'!$E$10 -> 26939.406 | T20: =+T18*'3a-SalesForecastYear1'!$E$10 -> 27478.194 | U20: =+U18*'3a-SalesForecastYear1'!$E$10 -> 28027.758 | V20: =+V18*'3a-SalesForecastYear1'!$E$10 -> 28588.313 | W20: =+W18*'3a-SalesForecastYear1'!$E$10 -> 29160.079 | X20: =+X18*'3a-SalesForecastYear1'!$E$10 -> 29743.281 | Y20: =+Y18*'3a-SalesForecastYear1'!$E$10 -> 30338.147 | ... AC20: =+AC18*'3a-SalesForecastYear1'!$E$10 -> 32838.985 | AD20: =SUM(R20:AC20) -> 354229.15 | AE20: =IF(AD19=0,0,AD20/AD19) -> 0.47619048 | AF20: =IF($AD$48=0,0,AD20/$AD$48) -> 0.5
A21: Margin | B21: ='3a-SalesForecastYear1'!O27 -> 118602 | C21: =C19-C20 -> 20988 | D21: =D19-D20 -> 21617.64 | E21: =E19-E20 -> 22266.169 | F21: =F19-F20 -> 22934.154 | G21: =G19-G20 -> 23622.179 | H21: =H19-H20 -> 24330.844 | I21: =I19-I20 -> 25060.77 | J21: =J19-J20 -> 25812.593 | ... N21: =N19-N20 -> 29052.3 | O21: =SUM(C21:N21) -> 297862.32 | P21: =IF(O19=0,0,O21/O19) -> 0.52380952 | Q21: =IF($O$49=0,0,O21/$O$49) -> 0.29752488 | R21: =R19-R20 -> 29052.3 | S21: =S19-S20 -> 29633.346 | T21: =T19-T20 -> 30226.013 | U21: =U19-U20 -> 30830.534 | V21: =V19-V20 -> 31447.144 | W21: =W19-W20 -> 32076.087 | X21: =X19-X20 -> 32717.609 | Y21: =Y19-Y20 -> 33371.961 | ... AC21: =AC19-AC20 -> 36122.884 | AD21: =SUM(R21:AC21) -> 389652.06 | AE21: =IF(AD19=0,0,AD21/AD19) -> 0.52380952 | AF21: =IF($AD$49=0,0,AD21/$AD$49) -> 0.29752488
A23: ='3a-SalesForecastYear1'!B29 -> Deferred Revenue - 1 Month (20%)
A24: =Unit3&" Sold" -> 1 Sold | B24: =Unit3_Annual -> 493 | C24: ='3a-SalesForecastYear1'!N30 -> 88 | D24: =C24+C24*$C$7 -> 90.64 | E24: =D24+D24*$C$7 -> 93.3592 | F24: =E24+E24*$C$7 -> 96.159976 | G24: =F24+F24*$C$7 -> 99.044775 | H24: =G24+G24*$C$7 -> 102.01612 | I24: =H24+H24*$C$7 -> 105.0766 | J24: =I24+I24*$C$7 -> 108.2289 | K24: =J24+J24*$C$7 -> 111.47577 | ... N24: =M24+M24*$C$7 -> 121.81258 | O24: =SUM(C24:N24) -> 1248.8986 | Q24: =IF($O$46=0,0,O24/$O$46) -> 0.26268657 | R24: =N24 -> 121.81258 | S24: =R24+R24*$C$8 -> 124.24883 | T24: =S24+S24*$C$8 -> 126.73381 | U24: =T24+T24*$C$8 -> 129.26849 | V24: =U24+U24*$C$8 -> 131.85385 | W24: =V24+V24*$C$8 -> 134.49093 | X24: =W24+W24*$C$8 -> 137.18075 | Y24: =X24+X24*$C$8 -> 139.92437 | Z24: =Y24+Y24*$C$8 -> 142.72285 | ... AC24: =AB24+AB24*$C$8 -> 151.45863 | AD24: =SUM(R24:AC24) -> 1633.7613 | AF24: =IF($AD$46=0,0,AD24/$AD$46) -> 0.26268657
A25: Total Sales | B25: =Category3_Annual_Sales -> 53244 | C25: =+C24*'3a-SalesForecastYear1'!$D$11 -> 9504 | D25: =+D24*'3a-SalesForecastYear1'!$D$11 -> 9789.12 | E25: =+E24*'3a-SalesForecastYear1'!$D$11 -> 10082.794 | F25: =+F24*'3a-SalesForecastYear1'!$D$11 -> 10385.277 | G25: =+G24*'3a-SalesForecastYear1'!$D$11 -> 10696.836 | H25: =+H24*'3a-SalesForecastYear1'!$D$11 -> 11017.741 | I25: =+I24*'3a-SalesForecastYear1'!$D$11 -> 11348.273 | J25: =+J24*'3a-SalesForecastYear1'!$D$11 -> 11688.721 | ... N25: =+N24*'3a-SalesForecastYear1'!$D$11 -> 13155.759 | O25: =SUM(C25:N25) -> 134881.05 | P25: =(P26+P27) -> 1 | Q25: =IF($O$47=0,0,O25/$O$47) -> 0.087431694 | R25: =+R24*'3a-SalesForecastYear1'!$D$11 -> 13155.759 | S25: =+S24*'3a-SalesForecastYear1'!$D$11 -> 13418.874 | T25: =+T24*'3a-SalesForecastYear1'!$D$11 -> 13687.251 | U25: =+U24*'3a-SalesForecastYear1'!$D$11 -> 13960.996 | V25: =+V24*'3a-SalesForecastYear1'!$D$11 -> 14240.216 | W25: =+W24*'3a-SalesForecastYear1'!$D$11 -> 14525.021 | X25: =+X24*'3a-SalesForecastYear1'!$D$11 -> 14815.521 | Y25: =+Y24*'3a-SalesForecastYear1'!$D$11 -> 15111.831 | ... AC25: =+AC24*'3a-SalesForecastYear1'!$D$11 -> 16357.532 | AD25: =SUM(R25:AC25) -> 176446.22 | AE25: =(AE26+AE27) -> 1 | AF25: =IF($AD$47=0,0,AD25/$AD$47) -> 0.087431694
A26: Total COGS | B26: ='3a-SalesForecastYear1'!O32 -> 0 | C26: =+C24*'3a-SalesForecastYear1'!$E$11 -> 0 | D26: =+D24*'3a-SalesForecastYear1'!$E$11 -> 0 | E26: =+E24*'3a-SalesForecastYear1'!$E$11 -> 0 | F26: =+F24*'3a-SalesForecastYear1'!$E$11 -> 0 | G26: =+G24*'3a-SalesForecastYear1'!$E$11 -> 0 | H26: =+H24*'3a-SalesForecastYear1'!$E$11 -> 0 | I26: =+I24*'3a-SalesForecastYear1'!$E$11 -> 0 | J26: =+J24*'3a-SalesForecastYear1'!$E$11 -> 0 | ... N26: =+N24*'3a-SalesForecastYear1'!$E$11 -> 0 | O26: =SUM(C26:N26) -> 0 | P26: =IF(O25=0,0,O26/O25) -> 0 | Q26: =IF($O$48=0,0,O26/$O$48) -> 0 | R26: =+R24*'3a-SalesForecastYear1'!$E$11 -> 0 | S26: =+S24*'3a-SalesForecastYear1'!$E$11 -> 0 | T26: =+T24*'3a-SalesForecastYear1'!$E$11 -> 0 | U26: =+U24*'3a-SalesForecastYear1'!$E$11 -> 0 | V26: =+V24*'3a-SalesForecastYear1'!$E$11 -> 0 | W26: =+W24*'3a-SalesForecastYear1'!$E$11 -> 0 | X26: =+X24*'3a-SalesForecastYear1'!$E$11 -> 0 | Y26: =+Y24*'3a-SalesForecastYear1'!$E$11 -> 0 | ... AC26: =+AC24*'3a-SalesForecastYear1'!$E$11 -> 0 | AD26: =SUM(R26:AC26) -> 0 | AE26: =IF(AD25=0,0,AD26/AD25) -> 0 | AF26: =IF($AD$48=0,0,AD26/$AD$48) -> 0
A27: Margin | B27: ='3a-SalesForecastYear1'!O33 -> 53244 | C27: =C25-C26 -> 9504 | D27: =D25-D26 -> 9789.12 | E27: =E25-E26 -> 10082.794 | F27: =F25-F26 -> 10385.277 | G27: =G25-G26 -> 10696.836 | H27: =H25-H26 -> 11017.741 | I27: =I25-I26 -> 11348.273 | J27: =J25-J26 -> 11688.721 | ... N27: =N25-N26 -> 13155.759 | O27: =SUM(C27:N27) -> 134881.05 | P27: =IF(O25=0,0,O27/O25) -> 1 | Q27: =IF($O$49=0,0,O27/$O$49) -> 0.13472825 | R27: =R25-R26 -> 13155.759 | S27: =S25-S26 -> 13418.874 | T27: =T25-T26 -> 13687.251 | U27: =U25-U26 -> 13960.996 | V27: =V25-V26 -> 14240.216 | W27: =W25-W26 -> 14525.021 | X27: =X25-X26 -> 14815.521 | Y27: =Y25-Y26 -> 15111.831 | ... AC27: =AC25-AC26 -> 16357.532 | AD27: =SUM(R27:AC27) -> 176446.22 | AE27: =IF(AD25=0,0,AD27/AD25) -> 1 | AF27: =IF($AD$49=0,0,AD27/$AD$49) -> 0.13472825
A29: ='3a-SalesForecastYear1'!B35 -> Deferred Revenue - 6 Months (10%)
A30: =Unit4&" Sold" -> 1 Sold | B30: =Unit4_Annual -> 159 | C30: ='3a-SalesForecastYear1'!N36 -> 35 | D30: =C30+C30*$C$7 -> 36.05 | E30: =D30+D30*$C$7 -> 37.1315 | F30: =E30+E30*$C$7 -> 38.245445 | G30: =F30+F30*$C$7 -> 39.392808 | H30: =G30+G30*$C$7 -> 40.574593 | I30: =H30+H30*$C$7 -> 41.79183 | J30: =I30+I30*$C$7 -> 43.045585 | K30: =J30+J30*$C$7 -> 44.336953 | ... N30: =M30+M30*$C$7 -> 48.448185 | O30: =SUM(C30:N30) -> 496.72103 | Q30: =IF($O$46=0,0,O30/$O$46) -> 0.10447761 | R30: =N30 -> 48.448185 | S30: =R30+R30*$C$8 -> 49.417149 | T30: =S30+S30*$C$8 -> 50.405492 | U30: =T30+T30*$C$8 -> 51.413602 | V30: =U30+U30*$C$8 -> 52.441874 | W30: =V30+V30*$C$8 -> 53.490712 | X30: =W30+W30*$C$8 -> 54.560526 | Y30: =X30+X30*$C$8 -> 55.651736 | Z30: =Y30+Y30*$C$8 -> 56.764771 | ... AC30: =AB30+AB30*$C$8 -> 60.239229 | AD30: =SUM(R30:AC30) -> 649.79141 | AF30: =IF($AD$46=0,0,AD30/$AD$46) -> 0.10447761
A31: Total Sales | B31: =Category4_Annual_Sales -> 8586 | C31: =+C30*'3a-SalesForecastYear1'!$D$12 -> 1890 | D31: =+D30*'3a-SalesForecastYear1'!$D$12 -> 1946.7 | E31: =+E30*'3a-SalesForecastYear1'!$D$12 -> 2005.101 | F31: =+F30*'3a-SalesForecastYear1'!$D$12 -> 2065.254 | G31: =+G30*'3a-SalesForecastYear1'!$D$12 -> 2127.2117 | H31: =+H30*'3a-SalesForecastYear1'!$D$12 -> 2191.028 | I31: =+I30*'3a-SalesForecastYear1'!$D$12 -> 2256.7588 | J31: =+J30*'3a-SalesForecastYear1'!$D$12 -> 2324.4616 | ... N31: =+N30*'3a-SalesForecastYear1'!$D$12 -> 2616.202 | O31: =SUM(C31:N31) -> 26822.936 | P31: =(P32+P33) -> 1 | Q31: =IF($O$47=0,0,O31/$O$47) -> 0.017386985 | R31: =+R30*'3a-SalesForecastYear1'!$D$12 -> 2616.202 | S31: =+S30*'3a-SalesForecastYear1'!$D$12 -> 2668.5261 | T31: =+T30*'3a-SalesForecastYear1'!$D$12 -> 2721.8966 | U31: =+U30*'3a-SalesForecastYear1'!$D$12 -> 2776.3345 | V31: =+V30*'3a-SalesForecastYear1'!$D$12 -> 2831.8612 | W31: =+W30*'3a-SalesForecastYear1'!$D$12 -> 2888.4984 | X31: =+X30*'3a-SalesForecastYear1'!$D$12 -> 2946.2684 | Y31: =+Y30*'3a-SalesForecastYear1'!$D$12 -> 3005.1938 | ... AC31: =+AC30*'3a-SalesForecastYear1'!$D$12 -> 3252.9184 | AD31: =SUM(R31:AC31) -> 35088.736 | AE31: =(AE32+AE33) -> 1 | AF31: =IF($AD$47=0,0,AD31/$AD$47) -> 0.017386985
A32: Total COGS | B32: ='3a-SalesForecastYear1'!O38 -> 0 | C32: =+C30*'3a-SalesForecastYear1'!$E$12 -> 0 | D32: =+D30*'3a-SalesForecastYear1'!$E$12 -> 0 | E32: =+E30*'3a-SalesForecastYear1'!$E$12 -> 0 | F32: =+F30*'3a-SalesForecastYear1'!$E$12 -> 0 | G32: =+G30*'3a-SalesForecastYear1'!$E$12 -> 0 | H32: =+H30*'3a-SalesForecastYear1'!$E$12 -> 0 | I32: =+I30*'3a-SalesForecastYear1'!$E$12 -> 0 | J32: =+J30*'3a-SalesForecastYear1'!$E$12 -> 0 | ... N32: =+N30*'3a-SalesForecastYear1'!$E$12 -> 0 | O32: =SUM(C32:N32) -> 0 | P32: =IF(O31=0,0,O32/O31) -> 0 | Q32: =IF($O$48=0,0,O32/$O$48) -> 0 | R32: =+R30*'3a-SalesForecastYear1'!$E$12 -> 0 | S32: =+S30*'3a-SalesForecastYear1'!$E$12 -> 0 | T32: =+T30*'3a-SalesForecastYear1'!$E$12 -> 0 | U32: =+U30*'3a-SalesForecastYear1'!$E$12 -> 0 | V32: =+V30*'3a-SalesForecastYear1'!$E$12 -> 0 | W32: =+W30*'3a-SalesForecastYear1'!$E$12 -> 0 | X32: =+X30*'3a-SalesForecastYear1'!$E$12 -> 0 | Y32: =+Y30*'3a-SalesForecastYear1'!$E$12 -> 0 | ... AC32: =+AC30*'3a-SalesForecastYear1'!$E$12 -> 0 | AD32: =SUM(R32:AC32) -> 0 | AE32: =IF(AD31=0,0,AD32/AD31) -> 0 | AF32: =IF($AD$48=0,0,AD32/$AD$48) -> 0
A33: Margin | B33: ='3a-SalesForecastYear1'!O39 -> 8586 | C33: =C31-C32 -> 1890 | D33: =D31-D32 -> 1946.7 | E33: =E31-E32 -> 2005.101 | F33: =F31-F32 -> 2065.254 | G33: =G31-G32 -> 2127.2117 | H33: =H31-H32 -> 2191.028 | I33: =I31-I32 -> 2256.7588 | J33: =J31-J32 -> 2324.4616 | ... N33: =N31-N32 -> 2616.202 | O33: =SUM(C33:N33) -> 26822.936 | P33: =IF(O31=0,0,O33/O31) -> 1 | Q33: =IF($O$49=0,0,O33/$O$49) -> 0.026792549 | R33: =R31-R32 -> 2616.202 | S33: =S31-S32 -> 2668.5261 | T33: =T31-T32 -> 2721.8966 | U33: =U31-U32 -> 2776.3345 | V33: =V31-V32 -> 2831.8612 | W33: =W31-W32 -> 2888.4984 | X33: =X31-X32 -> 2946.2684 | Y33: =Y31-Y32 -> 3005.1938 | ... AC33: =AC31-AC32 -> 3252.9184 | AD33: =SUM(R33:AC33) -> 35088.736 | AE33: =IF(AD31=0,0,AD33/AD31) -> 1 | AF33: =IF($AD$49=0,0,AD33/$AD$49) -> 0.026792549
A35: ='3a-SalesForecastYear1'!B41 -> Product 5
A36: =Unit5&" Sold" -> Sold | B36: =Unit5_Annual -> 0 | C36: ='3a-SalesForecastYear1'!N42 -> 0 | D36: =C36+C36*$C$7 -> 0 | E36: =D36+D36*$C$7 -> 0 | F36: =E36+E36*$C$7 -> 0 | G36: =F36+F36*$C$7 -> 0 | H36: =G36+G36*$C$7 -> 0 | I36: =H36+H36*$C$7 -> 0 | J36: =I36+I36*$C$7 -> 0 | K36: =J36+J36*$C$7 -> 0 | ... N36: =M36+M36*$C$7 -> 0 | O36: =SUM(C36:N36) -> 0 | Q36: =IF($O$46=0,0,O36/$O$46) -> 0 | R36: =N36 -> 0 | S36: =R36+R36*$C$8 -> 0 | T36: =S36+S36*$C$8 -> 0 | U36: =T36+T36*$C$8 -> 0 | V36: =U36+U36*$C$8 -> 0 | W36: =V36+V36*$C$8 -> 0 | X36: =W36+W36*$C$8 -> 0 | Y36: =X36+X36*$C$8 -> 0 | Z36: =Y36+Y36*$C$8 -> 0 | ... AC36: =AB36+AB36*$C$8 -> 0 | AD36: =SUM(R36:AC36) -> 0 | AF36: =IF($AD$46=0,0,AD36/$AD$46) -> 0
A37: Total Sales | B37: =Category5_Annual_Sales -> 0 | C37: =+C36*'3a-SalesForecastYear1'!$D$13 -> 0 | D37: =+D36*'3a-SalesForecastYear1'!$D$13 -> 0 | E37: =+E36*'3a-SalesForecastYear1'!$D$13 -> 0 | F37: =+F36*'3a-SalesForecastYear1'!$D$13 -> 0 | G37: =+G36*'3a-SalesForecastYear1'!$D$13 -> 0 | H37: =+H36*'3a-SalesForecastYear1'!$D$13 -> 0 | I37: =+I36*'3a-SalesForecastYear1'!$D$13 -> 0 | J37: =+J36*'3a-SalesForecastYear1'!$D$13 -> 0 | ... N37: =+N36*'3a-SalesForecastYear1'!$D$13 -> 0 | O37: =SUM(C37:N37) -> 0 | P37: =(P38+P39) -> 0 | Q37: =IF($O$47=0,0,O37/$O$47) -> 0 | R37: =+R36*'3a-SalesForecastYear1'!$D$13 -> 0 | S37: =+S36*'3a-SalesForecastYear1'!$D$13 -> 0 | T37: =+T36*'3a-SalesForecastYear1'!$D$13 -> 0 | U37: =+U36*'3a-SalesForecastYear1'!$D$13 -> 0 | V37: =+V36*'3a-SalesForecastYear1'!$D$13 -> 0 | W37: =+W36*'3a-SalesForecastYear1'!$D$13 -> 0 | X37: =+X36*'3a-SalesForecastYear1'!$D$13 -> 0 | Y37: =+Y36*'3a-SalesForecastYear1'!$D$13 -> 0 | ... AC37: =+AC36*'3a-SalesForecastYear1'!$D$13 -> 0 | AD37: =SUM(R37:AC37) -> 0 | AE37: =(AE38+AE39) -> 0 | AF37: =IF($AD$47=0,0,AD37/$AD$47) -> 0
A38: Total COGS | B38: ='3a-SalesForecastYear1'!O44 -> 0 | C38: =+C36*'3a-SalesForecastYear1'!$E$13 -> 0 | D38: =+D36*'3a-SalesForecastYear1'!$E$13 -> 0 | E38: =+E36*'3a-SalesForecastYear1'!$E$13 -> 0 | F38: =+F36*'3a-SalesForecastYear1'!$E$13 -> 0 | G38: =+G36*'3a-SalesForecastYear1'!$E$13 -> 0 | H38: =+H36*'3a-SalesForecastYear1'!$E$13 -> 0 | I38: =+I36*'3a-SalesForecastYear1'!$E$13 -> 0 | J38: =+J36*'3a-SalesForecastYear1'!$E$13 -> 0 | ... N38: =+N36*'3a-SalesForecastYear1'!$E$13 -> 0 | O38: =SUM(C38:N38) -> 0 | P38: =IF(O37=0,0,O38/O37) -> 0 | Q38: =IF($O$48=0,0,O38/$O$48) -> 0 | R38: =+R36*'3a-SalesForecastYear1'!$E$13 -> 0 | S38: =+S36*'3a-SalesForecastYear1'!$E$13 -> 0 | T38: =+T36*'3a-SalesForecastYear1'!$E$13 -> 0 | U38: =+U36*'3a-SalesForecastYear1'!$E$13 -> 0 | V38: =+V36*'3a-SalesForecastYear1'!$E$13 -> 0 | W38: =+W36*'3a-SalesForecastYear1'!$E$13 -> 0 | X38: =+X36*'3a-SalesForecastYear1'!$E$13 -> 0 | Y38: =+Y36*'3a-SalesForecastYear1'!$E$13 -> 0 | ... AC38: =+AC36*'3a-SalesForecastYear1'!$E$13 -> 0 | AD38: =SUM(R38:AC38) -> 0 | AE38: =IF(AD37=0,0,AD38/AD37) -> 0 | AF38: =IF($AD$48=0,0,AD38/$AD$48) -> 0
A39: Margin | B39: ='3a-SalesForecastYear1'!O45 -> 0 | C39: =C37-C38 -> 0 | D39: =D37-D38 -> 0 | E39: =E37-E38 -> 0 | F39: =F37-F38 -> 0 | G39: =G37-G38 -> 0 | H39: =H37-H38 -> 0 | I39: =I37-I38 -> 0 | J39: =J37-J38 -> 0 | ... N39: =N37-N38 -> 0 | O39: =SUM(C39:N39) -> 0 | P39: =IF(O37=0,0,O39/O37) -> 0 | Q39: =IF($O$49=0,0,O39/$O$49) -> 0 | R39: =R37-R38 -> 0 | S39: =S37-S38 -> 0 | T39: =T37-T38 -> 0 | U39: =U37-U38 -> 0 | V39: =V37-V38 -> 0 | W39: =W37-W38 -> 0 | X39: =X37-X38 -> 0 | Y39: =Y37-Y38 -> 0 | ... AC39: =AC37-AC38 -> 0 | AD39: =SUM(R39:AC39) -> 0 | AE39: =IF(AD37=0,0,AD39/AD37) -> 0 | AF39: =IF($AD$49=0,0,AD39/$AD$49) -> 0
A41: ='3a-SalesForecastYear1'!B47 -> Product 6
A42: =Unit6&" Sold" -> Sold | B42: =Unit6_Annual -> 0 | C42: ='3a-SalesForecastYear1'!N48 -> 0 | D42: =C42+C42*$C$7 -> 0 | E42: =D42+D42*$C$7 -> 0 | F42: =E42+E42*$C$7 -> 0 | G42: =F42+F42*$C$7 -> 0 | H42: =G42+G42*$C$7 -> 0 | I42: =H42+H42*$C$7 -> 0 | J42: =I42+I42*$C$7 -> 0 | K42: =J42+J42*$C$7 -> 0 | ... N42: =M42+M42*$C$7 -> 0 | O42: =SUM(C42:N42) -> 0 | Q42: =IF($O$46=0,0,O42/$O$46) -> 0 | R42: =N42 -> 0 | S42: =R42+R42*$C$8 -> 0 | T42: =S42+S42*$C$8 -> 0 | U42: =T42+T42*$C$8 -> 0 | V42: =U42+U42*$C$8 -> 0 | W42: =V42+V42*$C$8 -> 0 | X42: =W42+W42*$C$8 -> 0 | Y42: =X42+X42*$C$8 -> 0 | Z42: =Y42+Y42*$C$8 -> 0 | ... AC42: =AB42+AB42*$C$8 -> 0 | AD42: =SUM(R42:AC42) -> 0 | AF42: =IF($AD$46=0,0,AD42/$AD$46) -> 0
A43: Total Sales | B43: =Category6_Annual_Sales -> 0 | C43: =+C42*'3a-SalesForecastYear1'!$D$14 -> 0 | D43: =+D42*'3a-SalesForecastYear1'!$D$14 -> 0 | E43: =+E42*'3a-SalesForecastYear1'!$D$14 -> 0 | F43: =+F42*'3a-SalesForecastYear1'!$D$14 -> 0 | G43: =+G42*'3a-SalesForecastYear1'!$D$14 -> 0 | H43: =+H42*'3a-SalesForecastYear1'!$D$14 -> 0 | I43: =+I42*'3a-SalesForecastYear1'!$D$14 -> 0 | J43: =+J42*'3a-SalesForecastYear1'!$D$14 -> 0 | ... N43: =+N42*'3a-SalesForecastYear1'!$D$14 -> 0 | O43: =SUM(C43:N43) -> 0 | P43: =(P44+P45) -> 0 | Q43: =IF($O$47=0,0,O43/$O$47) -> 0 | R43: =+R42*'3a-SalesForecastYear1'!$D$14 -> 0 | S43: =+S42*'3a-SalesForecastYear1'!$D$14 -> 0 | T43: =+T42*'3a-SalesForecastYear1'!$D$14 -> 0 | U43: =+U42*'3a-SalesForecastYear1'!$D$14 -> 0 | V43: =+V42*'3a-SalesForecastYear1'!$D$14 -> 0 | W43: =+W42*'3a-SalesForecastYear1'!$D$14 -> 0 | X43: =+X42*'3a-SalesForecastYear1'!$D$14 -> 0 | Y43: =+Y42*'3a-SalesForecastYear1'!$D$14 -> 0 | ... AC43: =+AC42*'3a-SalesForecastYear1'!$D$14 -> 0 | AD43: =SUM(R43:AC43) -> 0 | AE43: =(AE44+AE45) -> 0 | AF43: =IF($AD$47=0,0,AD43/$AD$47) -> 0
A44: Total COGS | B44: ='3a-SalesForecastYear1'!O50 -> 0 | C44: =+C42*'3a-SalesForecastYear1'!$E$14 -> 0 | D44: =+D42*'3a-SalesForecastYear1'!$E$14 -> 0 | E44: =+E42*'3a-SalesForecastYear1'!$E$14 -> 0 | F44: =+F42*'3a-SalesForecastYear1'!$E$14 -> 0 | G44: =+G42*'3a-SalesForecastYear1'!$E$14 -> 0 | H44: =+H42*'3a-SalesForecastYear1'!$E$14 -> 0 | I44: =+I42*'3a-SalesForecastYear1'!$E$14 -> 0 | J44: =+J42*'3a-SalesForecastYear1'!$E$14 -> 0 | ... N44: =+N42*'3a-SalesForecastYear1'!$E$14 -> 0 | O44: =SUM(C44:N44) -> 0 | P44: =IF(O43=0,0,O44/O43) -> 0 | Q44: =IF($O$48=0,0,O44/$O$48) -> 0 | R44: =+R42*'3a-SalesForecastYear1'!$E$14 -> 0 | S44: =+S42*'3a-SalesForecastYear1'!$E$14 -> 0 | T44: =+T42*'3a-SalesForecastYear1'!$E$14 -> 0 | U44: =+U42*'3a-SalesForecastYear1'!$E$14 -> 0 | V44: =+V42*'3a-SalesForecastYear1'!$E$14 -> 0 | W44: =+W42*'3a-SalesForecastYear1'!$E$14 -> 0 | X44: =+X42*'3a-SalesForecastYear1'!$E$14 -> 0 | Y44: =+Y42*'3a-SalesForecastYear1'!$E$14 -> 0 | ... AC44: =+AC42*'3a-SalesForecastYear1'!$E$14 -> 0 | AD44: =SUM(R44:AC44) -> 0 | AE44: =IF(AD43=0,0,AD44/AD43) -> 0 | AF44: =IF($AD$48=0,0,AD44/$AD$48) -> 0
A45: Margin | B45: ='3a-SalesForecastYear1'!O51 -> 0 | C45: =C43-C44 -> 0 | D45: =D43-D44 -> 0 | E45: =E43-E44 -> 0 | F45: =F43-F44 -> 0 | G45: =G43-G44 -> 0 | H45: =H43-H44 -> 0 | I45: =I43-I44 -> 0 | J45: =J43-J44 -> 0 | ... N45: =N43-N44 -> 0 | O45: =SUM(C45:N45) -> 0 | P45: =IF(O43=0,0,O45/O43) -> 0 | Q45: =IF($O$49=0,0,O45/$O$49) -> 0 | R45: =R43-R44 -> 0 | S45: =S43-S44 -> 0 | T45: =T43-T44 -> 0 | U45: =U43-U44 -> 0 | V45: =V43-V44 -> 0 | W45: =W43-W44 -> 0 | X45: =X43-X44 -> 0 | Y45: =Y43-Y44 -> 0 | ... AC45: =AC43-AC44 -> 0 | AD45: =SUM(R45:AC45) -> 0 | AE45: =IF(AD43=0,0,AD45/AD43) -> 0 | AF45: =IF($AD$49=0,0,AD45/$AD$49) -> 0
A46: Total Units Sold | B46: =Units_Annual_Total -> 1850 | C46: =C12+C18+C24+C30+C36+C42 -> 335 | D46: =D12+D18+D24+D30+D36+D42 -> 345.05 | E46: =E12+E18+E24+E30+E36+E42 -> 355.4015 | F46: =F12+F18+F24+F30+F36+F42 -> 366.06354 | G46: =G12+G18+G24+G30+G36+G42 -> 377.04545 | H46: =H12+H18+H24+H30+H36+H42 -> 388.35681 | I46: =I12+I18+I24+I30+I36+I42 -> 400.00752 | J46: =J12+J18+J24+J30+J36+J42 -> 412.00774 | ... N46: =N12+N18+N24+N30+N36+N42 -> 463.71835 | O46: =SUM(C46:N46) -> 4754.3299 | R46: =R12+R18+R24+R30+R36+R42 -> 463.71835 | S46: =S12+S18+S24+S30+S36+S42 -> 472.99271 | T46: =T12+T18+T24+T30+T36+T42 -> 482.45257 | U46: =U12+U18+U24+U30+U36+U42 -> 492.10162 | V46: =V12+V18+V24+V30+V36+V42 -> 501.94365 | W46: =W12+W18+W24+W30+W36+W42 -> 511.98252 | X46: =X12+X18+X24+X30+X36+X42 -> 522.22218 | Y46: =Y12+Y18+Y24+Y30+Y36+Y42 -> 532.66662 | ... AC46: =AC12+AC18+AC24+AC30+AC36+AC42 -> 576.57548 | AD46: =SUM(R46:AC46) -> 6219.4321
A47: Total Sales | B47: =Sales_Annual_Total -> 611712 | C47: =C13+C19+C25+C31+C37+C43 -> 108702 | D47: =D13+D19+D25+D31+D37+D43 -> 111963.06 | E47: =E13+E19+E25+E31+E37+E43 -> 115321.95 | F47: =F13+F19+F25+F31+F37+F43 -> 118781.61 | G47: =G13+G19+G25+G31+G37+G43 -> 122345.06 | H47: =H13+H19+H25+H31+H37+H43 -> 126015.41 | I47: =I13+I19+I25+I31+I37+I43 -> 129795.87 | J47: =J13+J19+J25+J31+J37+J43 -> 133689.75 | ... N47: =N13+N19+N25+N31+N37+N43 -> 150468.99 | O47: =SUM(C47:N47) -> 1542702 | R47: =R13+R19+R25+R31+R37+R43 -> 150468.99 | S47: =S13+S19+S25+S31+S37+S43 -> 153478.37 | T47: =T13+T19+T25+T31+T37+T43 -> 156547.94 | U47: =U13+U19+U25+U31+U37+U43 -> 159678.9 | V47: =V13+V19+V25+V31+V37+V43 -> 162872.47 | W47: =W13+W19+W25+W31+W37+W43 -> 166129.92 | X47: =X13+X19+X25+X31+X37+X43 -> 169452.52 | Y47: =Y13+Y19+Y25+Y31+Y37+Y43 -> 172841.57 | ... AC47: =AC13+AC19+AC25+AC31+AC37+AC43 -> 187089.28 | AD47: =SUM(R47:AC47) -> 2018103.6
A48: Total Cost of Goods Sold | B48: =COGS_Annual_Total -> 215640 | C48: =C14+C20+C26+C32+C38+C44 -> 38160 | D48: =D14+D20+D26+D32+D38+D44 -> 39304.8 | E48: =E14+E20+E26+E32+E38+E44 -> 40483.944 | F48: =F14+F20+F26+F32+F38+F44 -> 41698.462 | G48: =G14+G20+G26+G32+G38+G44 -> 42949.416 | H48: =H14+H20+H26+H32+H38+H44 -> 44237.899 | I48: =I14+I20+I26+I32+I38+I44 -> 45565.036 | J48: =J14+J20+J26+J32+J38+J44 -> 46931.987 | ... N48: =N14+N20+N26+N32+N38+N44 -> 52822.365 | O48: =SUM(C48:N48) -> 541567.85 | R48: =R14+R20+R26+R32+R38+R44 -> 52822.365 | S48: =S14+S20+S26+S32+S38+S44 -> 53878.812 | T48: =T14+T20+T26+T32+T38+T44 -> 54956.388 | U48: =U14+U20+U26+U32+U38+U44 -> 56055.516 | V48: =V14+V20+V26+V32+V38+V44 -> 57176.626 | W48: =W14+W20+W26+W32+W38+W44 -> 58320.159 | X48: =X14+X20+X26+X32+X38+X44 -> 59486.562 | Y48: =Y14+Y20+Y26+Y32+Y38+Y44 -> 60676.293 | ... AC48: =AC14+AC20+AC26+AC32+AC38+AC44 -> 65677.971 | AD48: =SUM(R48:AC48) -> 708458.29
A49: Total Margin | B49: =Margin_Annual_Total -> 396072 | C49: =C47-C48 -> 70542 | D49: =D47-D48 -> 72658.26 | E49: =E47-E48 -> 74838.008 | F49: =F47-F48 -> 77083.148 | G49: =G47-G48 -> 79395.642 | H49: =H47-H48 -> 81777.512 | I49: =I47-I48 -> 84230.837 | J49: =J47-J48 -> 86757.762 | ... N49: =N47-N48 -> 97646.626 | O49: =O15+O21+O27+O33+O39+O45 -> 1001134.1 | R49: =R47-R48 -> 97646.626 | S49: =S47-S48 -> 99599.558 | T49: =T47-T48 -> 101591.55 | U49: =U47-U48 -> 103623.38 | V49: =V47-V48 -> 105695.85 | W49: =W47-W48 -> 107809.76 | X49: =X47-X48 -> 109965.96 | Y49: =Y47-Y48 -> 112165.28 | ... AC49: =AC47-AC48 -> 121411.31 | AD49: =AD15+AD21+AD27+AD33+AD39+AD45 -> 1309645.3

Sheet 4-AdditionalInputs
B2: Additional Inputs
B4: Prepared By: | C4: Company Name:
B5: =IF(ISBLANK(Directions!C10),"Owner",Directions!C10) -> Owner | C5: =IF(ISBLANK(Directions!D10),"Company 1",Directions!D10) -> Company 1
B7: Accounts Receivable (A/R) Days Sales Outstanding
B8: Percent of Collections | C8: Year 1 | D8: Year 2 | E8: Year 3
B9: Paid within 30 days | C9: 1 | D9: 1 | E9: 1
B10: Paid between 30 and 60 days | C10: 0 | D10: 0 | E10: 0
B11: Paid in more than 60 days | C11: 0 | D11: 0 | E11: 0
B12: Allowance for bad debt | C12: =1-SUM(C9:C11) -> 0 | D12: =1-SUM(D9:D11) -> 0 | E12: =1-SUM(E9:E11) -> 0
B13: This should equal 100% ----> | C13: =SUM(C9:C12) -> 1 | D13: =SUM(D9:D12) -> 1 | E13: =SUM(E9:E12) -> 1
B15: Accounts Payable (A/P)
B16: Percent of Disbursements | C16: Year 1 | D16: Year 2 | E16: Year 3
B17: Paid within 30 days | C17: 1 | D17: 1 | E17: 1
B18: Paid between 30 and 60 days | C18: 0 | D18: 0 | E18: 0
B19: Paid in more than 60 days | C19: 0 | D19: 0 | E19: 0
B20: This should equal 100% ----> | C20: =SUM(C17:C19) -> 1 | D20: =SUM(D17:D19) -> 1 | E20: =SUM(E17:E19) -> 1
B23: Line of Credit Assumptions
B24: Desired Minimum Cash Balance | D24: 0
B25: Line of Credit Interest Rate | D25: 0.08
B27: Additional Fixed Assets Purchases
B28: Fixed Assets | C28: Depreciation (years) | D28: ='2a-PayrollYear1'!F7 -> Month 1 | E28: ='2a-PayrollYear1'!G7 -> Month 2 | F28: ='2a-PayrollYear1'!H7 -> Month 3 | G28: ='2a-PayrollYear1'!I7 -> Month 4 | H28: ='2a-PayrollYear1'!J7 -> Month 5 | I28: ='2a-PayrollYear1'!K7 -> Month 6 | J28: ='2a-PayrollYear1'!L7 -> Month 7 | K28: ='2a-PayrollYear1'!M7 -> Month 8 | ... O28: ='2a-PayrollYear1'!Q7 -> Month 12 | P28: Year 1 Totals | Q28: Year 2 Total | R28: Year 3 Total
B29: Real Estate | C29: 20 | D29: =Buildings -> 0 | P29: =SUM(D29:O29) -> 0
B30: Leasehold Improvements | C30: 7 | D30: =LeaseImprovements -> 0 | P30: =SUM(D30:O30) -> 0
B31: Equipment | C31: 7 | D31: =Equipment -> 0 | P31: =SUM(D31:O31) -> 0
B32: Furniture and Fixtures | C32: 5 | D32: =Furniture -> 0 | P32: =SUM(D32:O32) -> 0
B33: Vehicles | C33: 5 | D33: =Vehicles -> 0 | P33: =SUM(D33:O33) -> 0
B34: Other Fixed Assets | C34: 5 | D34: =OtherFixedAssets -> 0 | P34: =SUM(D34:O34) -> 0 | Q34: 0 | R34: 0
B35: Total Additional Fixed Assets | D35: =SUM(D29:D34) -> 0 | E35: =SUM(E29:E34) -> 0 | F35: =SUM(F29:F34) -> 0 | G35: =SUM(G29:G34) -> 0 | H35: =SUM(H29:H34) -> 0 | I35: =SUM(I29:I34) -> 0 | J35: =SUM(J29:J34) -> 0 | K35: =SUM(K29:K34) -> 0 | ... R35: =SUM(R29:R34) -> 0
B38: Income Tax Assumptions
B39: Effective Income Tax Rate - Year 1 | C39: 0
B40: Effective Income Tax Rate - Year 2 | C40: 0
B41: Effective Income Tax Rate - Year 3 | C41: 0
B43: Amortization of Start-Up Costs
B44: Amortization Period in Years | C44: 3
B46: Reehash Business Model Parameters
B48: Lead Generation & Conversion
B49: Leads per contractor per day | C49: 10
B50: Show rate (% of scheduled consultations that show) | C50: 0.4
B51: Conversion rate (% of shows that sign) | C51: 0.2
B53: Contract & Fee Structure
...

Sheet 5a-OpExYear1
B2: Operating Expenses Year 1
B4: Prepared By: | C4: Company Name:
B5: =IF(ISBLANK(Directions!C10),"Owner",Directions!C10) -> Owner | C5: =IF(ISBLANK(Directions!D10),"Company 1",Directions!D10) -> Company 1
C8: ='2a-PayrollYear1'!F7 -> Month 1 | D8: ='2a-PayrollYear1'!G7 -> Month 2 | E8: ='2a-PayrollYear1'!H7 -> Month 3 | F8: ='2a-PayrollYear1'!I7 -> Month 4 | G8: ='2a-PayrollYear1'!J7 -> Month 5 | H8: ='2a-PayrollYear1'!K7 -> Month 6 | I8: ='2a-PayrollYear1'!L7 -> Month 7 | J8: ='2a-PayrollYear1'!M7 -> Month 8 | ... N8: ='2a-PayrollYear1'!Q7 -> Month 12 | O8: Annual Totals
B9: Expenses
B10: Advertising | O10: =SUM(C10:N10) -> 0
B11: Car and Truck Expenses | O11: =SUM(C11:N11) -> 0
